[2024-08-21T06:01:15.129+0000] {local_task_job_runner.py:120} INFO - ::group::Pre task execution logs
[2024-08-21T06:01:15.207+0000] {taskinstance.py:2076} INFO - Dependencies all met for dep_context=non-requeueable deps ti=<TaskInstance: etl_mega2024-08-21.validate_the_api scheduled__2024-05-16T00:00:00+00:00 [queued]>
[2024-08-21T06:01:15.234+0000] {taskinstance.py:2076} INFO - Dependencies all met for dep_context=requeueable deps ti=<TaskInstance: etl_mega2024-08-21.validate_the_api scheduled__2024-05-16T00:00:00+00:00 [queued]>
[2024-08-21T06:01:15.238+0000] {taskinstance.py:2306} INFO - Starting attempt 1 of 2
[2024-08-21T06:01:15.273+0000] {taskinstance.py:2330} INFO - Executing <Task(BashOperator): validate_the_api> on 2024-05-16 00:00:00+00:00
[2024-08-21T06:01:15.311+0000] {logging_mixin.py:188} WARNING - /home/***/.local/lib/python3.12/site-packages/***/task/task_runner/standard_task_runner.py:61 DeprecationWarning: This process (pid=304) is multi-threaded, use of fork() may lead to deadlocks in the child.
[2024-08-21T06:01:15.313+0000] {standard_task_runner.py:90} INFO - Running: ['***', 'tasks', 'run', 'etl_mega2024-08-21', 'validate_the_api', 'scheduled__2024-05-16T00:00:00+00:00', '--job-id', '28', '--raw', '--subdir', 'DAGS_FOLDER/final_etl.py', '--cfg-path', '/tmp/tmpsaw3osoa']
[2024-08-21T06:01:15.327+0000] {standard_task_runner.py:91} INFO - Job 28: Subtask validate_the_api
[2024-08-21T06:01:15.320+0000] {standard_task_runner.py:63} INFO - Started process 316 to run task
[2024-08-21T06:01:15.471+0000] {task_command.py:426} INFO - Running <TaskInstance: etl_mega2024-08-21.validate_the_api scheduled__2024-05-16T00:00:00+00:00 [running]> on host 7e1333882d71
[2024-08-21T06:01:15.979+0000] {taskinstance.py:2648} INFO - Exporting env vars: AIRFLOW_CTX_DAG_OWNER='***' AIRFLOW_CTX_DAG_ID='etl_mega2024-08-21' AIRFLOW_CTX_TASK_ID='validate_the_api' AIRFLOW_CTX_EXECUTION_DATE='2024-05-16T00:00:00+00:00' AIRFLOW_CTX_TRY_NUMBER='1' AIRFLOW_CTX_DAG_RUN_ID='scheduled__2024-05-16T00:00:00+00:00'
[2024-08-21T06:01:15.981+0000] {taskinstance.py:430} INFO - ::endgroup::
[2024-08-21T06:01:16.050+0000] {subprocess.py:63} INFO - Tmp dir root location: /tmp
[2024-08-21T06:01:16.069+0000] {subprocess.py:75} INFO - Running command: ['/usr/bin/bash', '-c', 'python3 /opt/***/data/api_utils.py']
[2024-08-21T06:01:16.113+0000] {subprocess.py:86} INFO - Output:
[2024-08-21T06:01:17.708+0000] {subprocess.py:97} INFO - Command exited with return code 0
[2024-08-21T06:01:17.762+0000] {taskinstance.py:441} INFO - ::group::Post task execution logs
[2024-08-21T06:01:18.062+0000] {taskinstance.py:1206} INFO - Marking task as SUCCESS. dag_id=etl_mega2024-08-21, task_id=validate_the_api, run_id=scheduled__2024-05-16T00:00:00+00:00, execution_date=20240516T000000, start_date=20240821T060115, end_date=20240821T060118
[2024-08-21T06:01:18.470+0000] {local_task_job_runner.py:240} INFO - Task exited with return code 0
[2024-08-21T06:01:18.779+0000] {taskinstance.py:3503} INFO - 1 downstream tasks scheduled from follow-on schedule check
[2024-08-21T06:01:18.788+0000] {local_task_job_runner.py:222} INFO - ::endgroup::
