[2024-08-12T08:58:44.682+0000] {local_task_job_runner.py:120} INFO - ::group::Pre task execution logs
[2024-08-12T08:58:44.705+0000] {taskinstance.py:2076} INFO - Dependencies all met for dep_context=non-requeueable deps ti=<TaskInstance: etl_2024-08-12.validate_the_data manual__2024-08-12T08:58:32.211830+00:00 [queued]>
[2024-08-12T08:58:44.764+0000] {taskinstance.py:2076} INFO - Dependencies all met for dep_context=requeueable deps ti=<TaskInstance: etl_2024-08-12.validate_the_data manual__2024-08-12T08:58:32.211830+00:00 [queued]>
[2024-08-12T08:58:44.766+0000] {taskinstance.py:2306} INFO - Starting attempt 1 of 2
[2024-08-12T08:58:44.878+0000] {taskinstance.py:2330} INFO - Executing <Task(BashOperator): validate_the_data> on 2024-08-12 08:58:32.211830+00:00
[2024-08-12T08:58:44.885+0000] {standard_task_runner.py:63} INFO - Started process 7410 to run task
[2024-08-12T08:58:44.892+0000] {standard_task_runner.py:90} INFO - Running: ['***', 'tasks', 'run', 'etl_2024-08-12', 'validate_the_data', 'manual__2024-08-12T08:58:32.211830+00:00', '--job-id', '3183', '--raw', '--subdir', 'DAGS_FOLDER/final_etl.py', '--cfg-path', '/tmp/tmp6rneyzcx']
[2024-08-12T08:58:44.896+0000] {standard_task_runner.py:91} INFO - Job 3183: Subtask validate_the_data
[2024-08-12T08:58:45.378+0000] {task_command.py:426} INFO - Running <TaskInstance: etl_2024-08-12.validate_the_data manual__2024-08-12T08:58:32.211830+00:00 [running]> on host 88a939613e48
[2024-08-12T08:58:46.332+0000] {taskinstance.py:2648} INFO - Exporting env vars: AIRFLOW_CTX_DAG_OWNER='***' AIRFLOW_CTX_DAG_ID='etl_2024-08-12' AIRFLOW_CTX_TASK_ID='validate_the_data' AIRFLOW_CTX_EXECUTION_DATE='2024-08-12T08:58:32.211830+00:00' AIRFLOW_CTX_TRY_NUMBER='1' AIRFLOW_CTX_DAG_RUN_ID='manual__2024-08-12T08:58:32.211830+00:00'
[2024-08-12T08:58:46.334+0000] {taskinstance.py:430} INFO - ::endgroup::
[2024-08-12T08:58:46.349+0000] {subprocess.py:63} INFO - Tmp dir root location: /tmp
[2024-08-12T08:58:46.350+0000] {subprocess.py:75} INFO - Running command: ['/usr/bin/bash', '-c', 'python3 /opt/***/data/validation_utils.py']
[2024-08-12T08:58:46.357+0000] {subprocess.py:86} INFO - Output:
[2024-08-12T08:58:46.578+0000] {subprocess.py:97} INFO - Command exited with return code 0
[2024-08-12T08:58:46.579+0000] {taskinstance.py:441} INFO - ::group::Post task execution logs
[2024-08-12T08:58:46.616+0000] {taskinstance.py:1206} INFO - Marking task as SUCCESS. dag_id=etl_2024-08-12, task_id=validate_the_data, run_id=manual__2024-08-12T08:58:32.211830+00:00, execution_date=20240812T085832, start_date=20240812T085844, end_date=20240812T085846
[2024-08-12T08:58:46.714+0000] {local_task_job_runner.py:240} INFO - Task exited with return code 0
[2024-08-12T08:58:46.757+0000] {taskinstance.py:3503} INFO - 1 downstream tasks scheduled from follow-on schedule check
[2024-08-12T08:58:46.776+0000] {local_task_job_runner.py:222} INFO - ::endgroup::
