[2024-08-21T06:14:36.036+0000] {local_task_job_runner.py:120} INFO - ::group::Pre task execution logs
[2024-08-21T06:14:36.067+0000] {taskinstance.py:2076} INFO - Dependencies all met for dep_context=non-requeueable deps ti=<TaskInstance: etl_22024-08-21.final_etl_processing scheduled__2024-05-29T00:00:00+00:00 [queued]>
[2024-08-21T06:14:36.075+0000] {taskinstance.py:2076} INFO - Dependencies all met for dep_context=requeueable deps ti=<TaskInstance: etl_22024-08-21.final_etl_processing scheduled__2024-05-29T00:00:00+00:00 [queued]>
[2024-08-21T06:14:36.075+0000] {taskinstance.py:2306} INFO - Starting attempt 2 of 2
[2024-08-21T06:14:36.087+0000] {taskinstance.py:2330} INFO - Executing <Task(BashOperator): final_etl_processing> on 2024-05-29 00:00:00+00:00
[2024-08-21T06:14:36.094+0000] {standard_task_runner.py:90} INFO - Running: ['***', 'tasks', 'run', 'etl_22024-08-21', 'final_etl_processing', 'scheduled__2024-05-29T00:00:00+00:00', '--job-id', '316', '--raw', '--subdir', 'DAGS_FOLDER/final_etl.py', '--cfg-path', '/tmp/tmpv3e1z5iz']
[2024-08-21T06:14:36.097+0000] {standard_task_runner.py:91} INFO - Job 316: Subtask final_etl_processing
[2024-08-21T06:14:36.100+0000] {logging_mixin.py:188} WARNING - /home/***/.local/lib/python3.12/site-packages/***/task/task_runner/standard_task_runner.py:61 DeprecationWarning: This process (pid=1992) is multi-threaded, use of fork() may lead to deadlocks in the child.
[2024-08-21T06:14:36.102+0000] {standard_task_runner.py:63} INFO - Started process 1997 to run task
[2024-08-21T06:14:36.148+0000] {task_command.py:426} INFO - Running <TaskInstance: etl_22024-08-21.final_etl_processing scheduled__2024-05-29T00:00:00+00:00 [running]> on host 7e1333882d71
[2024-08-21T06:14:36.251+0000] {taskinstance.py:2648} INFO - Exporting env vars: AIRFLOW_CTX_DAG_OWNER='***' AIRFLOW_CTX_DAG_ID='etl_22024-08-21' AIRFLOW_CTX_TASK_ID='final_etl_processing' AIRFLOW_CTX_EXECUTION_DATE='2024-05-29T00:00:00+00:00' AIRFLOW_CTX_TRY_NUMBER='2' AIRFLOW_CTX_DAG_RUN_ID='scheduled__2024-05-29T00:00:00+00:00'
[2024-08-21T06:14:36.252+0000] {taskinstance.py:430} INFO - ::endgroup::
[2024-08-21T06:14:36.266+0000] {subprocess.py:63} INFO - Tmp dir root location: /tmp
[2024-08-21T06:14:36.268+0000] {subprocess.py:75} INFO - Running command: ['/usr/bin/bash', '-c', "python3 /opt/***/data/etl_m12.py --connection postgresql+psycopg2://***:***@postgres/postgres --csv ''"]
[2024-08-21T06:14:36.285+0000] {subprocess.py:86} INFO - Output:
[2024-08-21T06:14:39.462+0000] {subprocess.py:93} INFO - /opt/***/data/etl_m12.py:23: MovedIn20Warning: Deprecated API features detected! These feature(s) are not compatible with SQLAlchemy 2.0. To prevent incompatible upgrades prior to updating applications, ensure requirements files are pinned to "sqlalchemy<2.0". Set environment variable SQLALCHEMY_WARN_20=1 to show all deprecation warnings.  Set environment variable SQLALCHEMY_SILENCE_UBER_WARNING=1 to silence this message. (Background on SQLAlchemy 2.0 at: https://sqlalche.me/e/b8d9)
[2024-08-21T06:14:39.474+0000] {subprocess.py:93} INFO -   Base = declarative_base()
[2024-08-21T06:14:39.486+0000] {subprocess.py:93} INFO - ERROR:root:Error fetching data from API: HTTPConnectionPool(host='localhost', port=3000): Max retries exceeded with url: /getData (Caused by NewConnectionError('<urllib3.connection.HTTPConnection object at 0xffff7e3af410>: Failed to establish a new connection: [Errno 111] Connection refused'))
[2024-08-21T06:14:39.494+0000] {subprocess.py:93} INFO - ERROR:__main__:No decrypted data found.
[2024-08-21T06:14:39.910+0000] {subprocess.py:97} INFO - Command exited with return code 1
[2024-08-21T06:14:39.927+0000] {taskinstance.py:441} INFO - ::group::Post task execution logs
[2024-08-21T06:14:40.120+0000] {taskinstance.py:2905} ERROR - Task failed with exception
Traceback (most recent call last):
  File "/home/airflow/.local/lib/python3.12/site-packages/airflow/models/taskinstance.py", line 465, in _execute_task
    result = _execute_callable(context=context, **execute_callable_kwargs)
             ^^^^^^^^^^^^^^^^^^^^^^^^^^^^^^^^^^^^^^^^^^^^^^^^^^^^^^^^^^^^^
  File "/home/airflow/.local/lib/python3.12/site-packages/airflow/models/taskinstance.py", line 432, in _execute_callable
    return execute_callable(context=context, **execute_callable_kwargs)
           ^^^^^^^^^^^^^^^^^^^^^^^^^^^^^^^^^^^^^^^^^^^^^^^^^^^^^^^^^^^^
  File "/home/airflow/.local/lib/python3.12/site-packages/airflow/models/baseoperator.py", line 401, in wrapper
    return func(self, *args, **kwargs)
           ^^^^^^^^^^^^^^^^^^^^^^^^^^^
  File "/home/airflow/.local/lib/python3.12/site-packages/airflow/operators/bash.py", line 243, in execute
    raise AirflowException(
airflow.exceptions.AirflowException: Bash command failed. The command returned a non-zero exit code 1.
[2024-08-21T06:14:40.139+0000] {taskinstance.py:1206} INFO - Marking task as FAILED. dag_id=etl_22024-08-21, task_id=final_etl_processing, run_id=scheduled__2024-05-29T00:00:00+00:00, execution_date=20240529T000000, start_date=20240821T061436, end_date=20240821T061440
[2024-08-21T06:14:40.510+0000] {standard_task_runner.py:110} ERROR - Failed to execute job 316 for task final_etl_processing (Bash command failed. The command returned a non-zero exit code 1.; 1997)
[2024-08-21T06:14:40.768+0000] {local_task_job_runner.py:240} INFO - Task exited with return code 1
[2024-08-21T06:14:41.667+0000] {local_task_job_runner.py:222} INFO - ::endgroup::
