[2024-08-07T10:40:05.816+0000] {local_task_job_runner.py:120} INFO - ::group::Pre task execution logs
[2024-08-07T10:40:05.833+0000] {taskinstance.py:2076} INFO - Dependencies all met for dep_context=non-requeueable deps ti=<TaskInstance: data_migrations2024-08-07.fetch_the_api scheduled__2024-05-08T00:00:00+00:00 [queued]>
[2024-08-07T10:40:05.836+0000] {taskinstance.py:2076} INFO - Dependencies all met for dep_context=requeueable deps ti=<TaskInstance: data_migrations2024-08-07.fetch_the_api scheduled__2024-05-08T00:00:00+00:00 [queued]>
[2024-08-07T10:40:05.837+0000] {taskinstance.py:2306} INFO - Starting attempt 1 of 2
[2024-08-07T10:40:05.873+0000] {taskinstance.py:2330} INFO - Executing <Task(BashOperator): fetch_the_api> on 2024-05-08 00:00:00+00:00
[2024-08-07T10:40:05.876+0000] {standard_task_runner.py:63} INFO - Started process 1317 to run task
[2024-08-07T10:40:05.878+0000] {standard_task_runner.py:90} INFO - Running: ['***', 'tasks', 'run', 'data_migrations2024-08-07', 'fetch_the_api', 'scheduled__2024-05-08T00:00:00+00:00', '--job-id', '4', '--raw', '--subdir', 'DAGS_FOLDER/data_migrations.py', '--cfg-path', '/tmp/tmp5feqp6mz']
[2024-08-07T10:40:05.879+0000] {standard_task_runner.py:91} INFO - Job 4: Subtask fetch_the_api
[2024-08-07T10:40:05.974+0000] {task_command.py:426} INFO - Running <TaskInstance: data_migrations2024-08-07.fetch_the_api scheduled__2024-05-08T00:00:00+00:00 [running]> on host 8cffaad11d99
[2024-08-07T10:40:06.234+0000] {taskinstance.py:2648} INFO - Exporting env vars: AIRFLOW_CTX_DAG_OWNER='***' AIRFLOW_CTX_DAG_ID='data_migrations2024-08-07' AIRFLOW_CTX_TASK_ID='fetch_the_api' AIRFLOW_CTX_EXECUTION_DATE='2024-05-08T00:00:00+00:00' AIRFLOW_CTX_TRY_NUMBER='1' AIRFLOW_CTX_DAG_RUN_ID='scheduled__2024-05-08T00:00:00+00:00'
[2024-08-07T10:40:06.261+0000] {taskinstance.py:430} INFO - ::endgroup::
[2024-08-07T10:40:06.273+0000] {subprocess.py:63} INFO - Tmp dir root location: /tmp
[2024-08-07T10:40:06.273+0000] {subprocess.py:75} INFO - Running command: ['/usr/bin/bash', '-c', 'python3 /opt/***/data/etl_m12_local_db.py']
[2024-08-07T10:40:06.280+0000] {subprocess.py:86} INFO - Output:
[2024-08-07T10:40:07.193+0000] {subprocess.py:93} INFO - Error occurred: (psycopg2.errors.UniqueViolation) duplicate key value violates unique constraint "pg_class_relname_nsp_index"
[2024-08-07T10:40:07.193+0000] {subprocess.py:93} INFO - DETAIL:  Key (relname, relnamespace)=(logs_id_seq, 2200) already exists.
[2024-08-07T10:40:07.193+0000] {subprocess.py:93} INFO - 
[2024-08-07T10:40:07.193+0000] {subprocess.py:93} INFO - [SQL:
[2024-08-07T10:40:07.194+0000] {subprocess.py:93} INFO - CREATE TABLE logs (
[2024-08-07T10:40:07.194+0000] {subprocess.py:93} INFO - 	id SERIAL NOT NULL,
[2024-08-07T10:40:07.194+0000] {subprocess.py:93} INFO - 	error VARCHAR,
[2024-08-07T10:40:07.194+0000] {subprocess.py:93} INFO - 	token VARCHAR,
[2024-08-07T10:40:07.194+0000] {subprocess.py:93} INFO - 	error_details TEXT,
[2024-08-07T10:40:07.194+0000] {subprocess.py:93} INFO - 	created_at TIMESTAMP WITHOUT TIME ZONE,
[2024-08-07T10:40:07.195+0000] {subprocess.py:93} INFO - 	PRIMARY KEY (id)
[2024-08-07T10:40:07.195+0000] {subprocess.py:93} INFO - )
[2024-08-07T10:40:07.195+0000] {subprocess.py:93} INFO - 
[2024-08-07T10:40:07.195+0000] {subprocess.py:93} INFO - ]
[2024-08-07T10:40:07.195+0000] {subprocess.py:93} INFO - (Background on this error at: https://sqlalche.me/e/14/gkpj)
[2024-08-07T10:40:07.223+0000] {subprocess.py:97} INFO - Command exited with return code 1
[2024-08-07T10:40:07.224+0000] {taskinstance.py:441} INFO - ::group::Post task execution logs
[2024-08-07T10:40:07.235+0000] {taskinstance.py:2905} ERROR - Task failed with exception
Traceback (most recent call last):
  File "/home/airflow/.local/lib/python3.9/site-packages/airflow/models/taskinstance.py", line 465, in _execute_task
    result = _execute_callable(context=context, **execute_callable_kwargs)
  File "/home/airflow/.local/lib/python3.9/site-packages/airflow/models/taskinstance.py", line 432, in _execute_callable
    return execute_callable(context=context, **execute_callable_kwargs)
  File "/home/airflow/.local/lib/python3.9/site-packages/airflow/models/baseoperator.py", line 401, in wrapper
    return func(self, *args, **kwargs)
  File "/home/airflow/.local/lib/python3.9/site-packages/airflow/operators/bash.py", line 243, in execute
    raise AirflowException(
airflow.exceptions.AirflowException: Bash command failed. The command returned a non-zero exit code 1.
[2024-08-07T10:40:07.238+0000] {taskinstance.py:1206} INFO - Marking task as UP_FOR_RETRY. dag_id=data_migrations2024-08-07, task_id=fetch_the_api, run_id=scheduled__2024-05-08T00:00:00+00:00, execution_date=20240508T000000, start_date=20240807T104005, end_date=20240807T104007
[2024-08-07T10:40:07.289+0000] {standard_task_runner.py:110} ERROR - Failed to execute job 4 for task fetch_the_api (Bash command failed. The command returned a non-zero exit code 1.; 1317)
[2024-08-07T10:40:07.294+0000] {local_task_job_runner.py:240} INFO - Task exited with return code 1
[2024-08-07T10:40:07.303+0000] {taskinstance.py:3503} INFO - 0 downstream tasks scheduled from follow-on schedule check
[2024-08-07T10:40:07.344+0000] {local_task_job_runner.py:222} INFO - ::endgroup::
